<?xml version="1.0" ?><!-- =================================================================================== --><!-- |    This document was autogenerated by xacro from /home/pstrawse/groovy_workspace/drc_configuration/xacro/V1_sim.xacro | --><!-- |    EDITING THIS FILE BY HAND IS NOT RECOMMENDED                                 | --><!-- =================================================================================== --><robot name="V1" xmlns:xacro="http://www.ros.org/wiki/xacro">
    <!-- ======================================================= -->
    <!-- DO NOT MODIFY URDF BY HAND! YOU ARE A FOOL IF YOU DO! -->
    <!-- ======================================================= -->
    <material name="White">
        <color rgba="1.0 1.0 1.0 1.0"/>
    </material>
    <material name="Gold">
        <color rgba="1.0 0.67 0 1.0"/>
    </material>
    <material name="Gray">
        <color rgba="0.5 0.5 0.5 1.0"/>
    </material>
    <material name="Pink">
        <color rgba="0.8 0 0.45 1.0"/>
    </material>
    
    
    
    <link name="Pelvis">
        <inertial>
            <mass value="6.95"/>
            <origin rpy="0 0 0" xyz="0.0005 -0.0009 -0.0704"/>
            <inertia ixx="0.147396179167" ixy="0.0" ixz="0.0" iyy="0.125244791667" iyz="0.0" izz="0.114921145833"/>
        </inertial>
        
        
    <collision><geometry><cylinder length="0.18" radius="0.18"/></geometry><origin rpy="0 0 0" xyz="0 0 -0.09"/></collision><collision><geometry><sphere radius="0.18"/></geometry><origin xyz="0 0 -0.18"/></collision><visual><geometry><cylinder length="0.18" radius="0.18"/></geometry><origin rpy="0 0 0" xyz="0 0 -0.09"/><material name="White"/></visual><visual><geometry><sphere radius="0.18"/></geometry><origin xyz="0 0 -0.18"/></visual></link>
    
    <link name="RightPelvisIMU_Frame">
        <inertial>
            <mass value="0.018"/>
            <origin rpy="0 0 0" xyz="0 0 0"/>
            <inertia ixx="3.0855e-06" ixy="0.0" ixz="0.0" iyy="3.768e-06" iyz="0.0" izz="1.0455e-06"/>
        </inertial>
        
        
    </link>
    
    <joint name="RightPelvisIMU_Offset" type="fixed">
        <origin rpy="-1.57079632679 0 1.275" xyz=".0459 -.1219 -.0423"/>
        <axis xyz="0 0 1"/>
        <parent link="Pelvis"/>
        <child link="RightPelvisIMU_Frame"/>
    </joint>
    <link name="LeftPelvisIMU_Frame">
        <inertial>
            <mass value="0.018"/>
            <origin rpy="0 0 0" xyz="0 0 0"/>
            <inertia ixx="3.0855e-06" ixy="0.0" ixz="0.0" iyy="3.768e-06" iyz="0.0" izz="1.0455e-06"/>
        </inertial>
        
        
    </link>
    
    <joint name="LeftPelvisIMU_Offset" type="fixed">
        <origin rpy="1.57079632679 0 -1.275" xyz=".0459 .1219 -.0423"/>
        <axis xyz="0 0 1"/>
        <parent link="Pelvis"/>
        <child link="LeftPelvisIMU_Frame"/>
    </joint>
    <link name="Trunk">
        <inertial>
            <mass value="41.9"/>
            <origin rpy="0 0 0" xyz="0.255 0 -0.0981"/>
            <inertia ixx="1.18918135833" ixy="0.0" ixz="0.0" iyy="1.42217329167" iyz="0.0" izz="1.35591891667"/>
        </inertial>
        
        
    <collision><geometry><cylinder length="0.4" radius="0.18"/></geometry><origin rpy="0 1.57079632679 0" xyz="0.2 0 -0.04"/></collision><collision><geometry><cylinder length="0.3" radius="0.15"/></geometry><origin rpy="1.57079632679 0 0" xyz="0.23 0 -0.005"/></collision><collision><geometry><box size="0.4 0.36 0.3"/></geometry><origin rpy="0 0 0" xyz="0.25 0 -0.2"/></collision><visual><geometry><cylinder length="0.4" radius="0.18"/></geometry><origin rpy="0 1.57079632679 0" xyz="0.2 0 -0.04"/><material name="White"/></visual><visual><geometry><cylinder length="0.3" radius="0.15"/></geometry><origin rpy="1.57079632679 0 0" xyz="0.23 0 -0.005"/></visual><visual><geometry><box size="0.4 0.36 0.3"/></geometry><origin rpy="0 0 0" xyz="0.25 0 -0.2"/></visual></link>
    
    <link name="WaistRotator">
        <!-- Virtual Link -->
        <inertial>
            <mass value="0.1"/>
            <origin rpy="0 0 0" xyz="0 0 0"/>
            <inertia ixx="8.33333333333e-05" ixy="0.0" ixz="0.0" iyy="8.33333333333e-05" iyz="0.0" izz="0.000125"/>
        </inertial>
    </link>
    <link name="WaistExtensor">
        <!-- Virtual Link -->
        <inertial>
            <mass value="0.1"/>
            <origin rpy="0 0 0" xyz="0 0 0"/>
            <inertia ixx="8.33333333333e-05" ixy="0.0" ixz="0.0" iyy="8.33333333333e-05" iyz="0.0" izz="0.000125"/>
        </inertial>
    </link>
    <joint name="WaistRotator" type="revolute">
        <origin rpy="0 0 0" xyz="0 0 0"/>
        <axis xyz="0 0 1"/>
        <parent link="Pelvis"/>
        <child link="WaistRotator"/>
        <limit effort="190" lower="-0.6981317004" upper="0.6981317004" velocity="5.89"/>
        <controller_gains Kd="400" Kp="20000"/>
        <dynamics damping="1.0" friction="0.0"/>
    </joint>
    
    <joint name="WaistExtensor" type="revolute">
        <origin rpy="1.57079632679 0 0" xyz="0.04191 0 0"/>
        <axis xyz="0 0 1"/>
        <parent link="WaistRotator"/>
        <child link="WaistExtensor"/>
        <limit effort="150" lower="-0.6981317004" upper="0.08726646255" velocity="9"/>
        <controller_gains Kd="400" Kp="20000"/>
        <dynamics damping="1.0" friction="0.0"/>
    </joint>
    
    <joint name="WaistLateralExtensor" type="revolute">
        <origin rpy="1.57079632679 0 1.57079632679" xyz="0 0.020352 0"/>
        <axis xyz="0 0 1"/>
        <parent link="WaistExtensor"/>
        <child link="Trunk"/>
        <limit effort="150" lower="-0.26179938765" upper="0.26179938765" velocity="9"/>
        <controller_gains Kd="400" Kp="20000"/>
        <dynamics damping="1.0" friction="0.0"/>
    </joint>
    
    
    
    
    
    
    
    <link name="RightIMU_Frame">
        <inertial>
            <mass value="0.018"/>
            <origin rpy="0 0 0" xyz="0 0 0"/>
            <inertia ixx="3.0855e-06" ixy="0.0" ixz="0.0" iyy="3.768e-06" iyz="0.0" izz="1.0455e-06"/>
        </inertial>
        
        
    </link>
    
    <joint name="RightIMU_Offset" type="fixed">
        <origin rpy="-1.57079632679 1.57079632679 0" xyz="0.363038 0.134239 -0.0468630"/>
        <axis xyz="0 0 1"/>
        <parent link="Trunk"/>
        <child link="RightIMU_Frame"/>
    </joint>
    <link name="LeftIMU_Frame">
        <inertial>
            <mass value="0.018"/>
            <origin rpy="0 0 0" xyz="0 0 0"/>
            <inertia ixx="3.0855e-06" ixy="0.0" ixz="0.0" iyy="3.768e-06" iyz="0.0" izz="1.0455e-06"/>
        </inertial>
        
        
    </link>
    
    <joint name="LeftIMU_Offset" type="fixed">
        <origin rpy="1.57079632679 1.57079632679 0" xyz="0.363038 -0.134239  -0.0468630"/>
        <axis xyz="0 0 1"/>
        <parent link="Trunk"/>
        <child link="LeftIMU_Frame"/>
    </joint>
    <link name="RightHazardCamera_Frame">
        <!-- Virtual Link -->
        <inertial>
            <mass value="0.1"/>
            <origin rpy="0 0 0" xyz="0 0 0"/>
            <inertia ixx="8.33333333333e-05" ixy="0.0" ixz="0.0" iyy="8.33333333333e-05" iyz="0.0" izz="0.000125"/>
        </inertial>
    </link>
    
    <joint name="RightHazardCamera_Offset" type="fixed">
        <origin rpy="0 0 0" xyz="0.0446987 0.0406146 0.0182674"/>
        <axis xyz="0 0 1"/>
        <parent link="Trunk"/>
        <child link="RightHazardCamera_Frame"/>
    </joint>
    <link name="LeftHazardCamera_Frame">
        <!-- Virtual Link -->
        <inertial>
            <mass value="0.1"/>
            <origin rpy="0 0 0" xyz="0 0 0"/>
            <inertia ixx="8.33333333333e-05" ixy="0.0" ixz="0.0" iyy="8.33333333333e-05" iyz="0.0" izz="0.000125"/>
        </inertial>
    </link>
    
    <joint name="LeftHazardCamera_Offset" type="fixed">
        <origin rpy="0 0 0" xyz="0.0446987 -0.0406146 0.0182674"/>
        <axis xyz="0 0 1"/>
        <parent link="Trunk"/>
        <child link="LeftHazardCamera_Frame"/>
    </joint>
    <link name="StereoHazardCamera_Frame">
        <!-- Virtual Link -->
        <inertial>
            <mass value="0.1"/>
            <origin rpy="0 0 0" xyz="0 0 0"/>
            <inertia ixx="8.33333333333e-05" ixy="0.0" ixz="0.0" iyy="8.33333333333e-05" iyz="0.0" izz="0.000125"/>
        </inertial>
    </link>
    <joint name="StereoHazardCamera_Offset" type="fixed">
        <origin rpy="0 0 1.57" xyz=".1723 -0.04535 0.0344"/>
        <axis xyz="0 0 1"/>
        <parent link="Trunk"/>
        <child link="StereoHazardCamera_Frame"/>
    </joint>
    <link name="LowerNeckExtensor">
        <!-- Virtual Link -->
        <inertial>
            <mass value="0.1"/>
            <origin rpy="0 0 0" xyz="0 0 0"/>
            <inertia ixx="8.33333333333e-05" ixy="0.0" ixz="0.0" iyy="8.33333333333e-05" iyz="0.0" izz="0.000125"/>
        </inertial>
        
        
    </link>
    <link name="NeckRotator">
        <!-- Virtual Link -->
        <inertial>
            <mass value="0.1"/>
            <origin rpy="0 0 0" xyz="0 0 0"/>
            <inertia ixx="8.33333333333e-05" ixy="0.0" ixz="0.0" iyy="8.33333333333e-05" iyz="0.0" izz="0.000125"/>
        </inertial>
        
        
    </link>
    <link name="Head">
        <inertial>
            <mass value="3.842"/>
            <origin rpy="0 0 0" xyz="-0.079 0.009 0"/>
            <inertia ixx="0.03012128" ixy="0.0" ixz="0.0" iyy="0.03012128" iyz="0.0" izz="0.03012128"/>
        </inertial>
        
        
    <collision><geometry><sphere radius="0.14"/></geometry><origin xyz="-0.09 0 0"/></collision><visual><geometry><sphere radius="0.14"/></geometry><origin xyz="-0.09 0 0"/><material name="White"/></visual></link>
    
    <joint name="LowerNeckExtensor" type="revolute">
        <origin rpy="-1.57079632679 0 0" xyz="0.3383 0 0.0519"/>
        <axis xyz="0 0 1"/>
        <parent link="Trunk"/>
        <child link="LowerNeckExtensor"/>
        <limit effort="26" lower="-1.5707963259" upper="0" velocity="5"/>
        <controller_gains Kd="0" Kp="20000"/>
        <dynamics damping="1.0" friction="0.0"/>
    </joint>
    
    <joint name="NeckRotator" type="revolute">
        <origin rpy="1.57079632679 0 1.57079632679" xyz="0 0.0519 0"/>
        <axis xyz="0 0 1"/>
        <parent link="LowerNeckExtensor"/>
        <child link="NeckRotator"/>
        <limit effort="26" lower="-1.5707963259" upper="1.5707963259" velocity="5"/>
        <controller_gains Kd="0" Kp="20000"/>
        <dynamics damping="1.0" friction="0.0"/>
    </joint>
    
    <joint name="UpperNeckExtensor" type="revolute">
        <origin rpy="-1.57079632679 0 0" xyz="0.06 0 0.196"/>
        <axis xyz="0 0 1"/>
        <parent link="NeckRotator"/>
        <child link="Head"/>
<!--        <limit effort="26" lower="-0.08726646255" upper="0.78539816295" velocity="5"/> -->
        <limit effort="26" lower="-0.15" upper="0.78539816295" velocity="5"/>
        <controller_gains Kd="0" Kp="20000"/>
        <dynamics damping="1.0" friction="0.0"/>
    </joint>
    
    
    
    
    
    
    
    <link name="HeadCamBoard_Frame">
        <!-- Virtual Link -->
        <inertial>
            <mass value="0.1"/>
            <origin rpy="0 0 0" xyz="0 0 0"/>
            <inertia ixx="8.33333333333e-05" ixy="0.0" ixz="0.0" iyy="8.33333333333e-05" iyz="0.0" izz="0.000125"/>
        </inertial>
    </link>
    
    <joint name="HeadCamBoard_Offset" type="fixed">
        <origin rpy="1.57079632679 3.14159265359 -.61" xyz="-0.186861111 0.085358875 -0.008499998"/>
        <axis xyz="0 0 1"/>
        <parent link="Head"/>
        <child link="HeadCamBoard_Frame"/>
    </joint>
    <link name="HeadCamBoardIR_Frame">
        <!-- Virtual Link -->
        <inertial>
            <mass value="0.1"/>
            <origin rpy="0 0 0" xyz="0 0 0"/>
            <inertia ixx="8.33333333333e-05" ixy="0.0" ixz="0.0" iyy="8.33333333333e-05" iyz="0.0" izz="0.000125"/>
        </inertial>
    </link>
    <joint name="HeadCamBoardIR_Offset" type="fixed">
        <origin rpy="-1.4279169 0.057186 -1.603747" xyz="-0.05180 -0.0013 0.030237"/>
        <axis xyz="0 0 1"/>
        <parent link="HeadCamBoard_Frame"/>
        <child link="HeadCamBoardIR_Frame"/>
    </joint>
    <link name="Ibeo_Frame">
        <!-- Virtual Link -->
        <inertial>
            <mass value="0.1"/>
            <origin rpy="0 0 0" xyz="0 0 0"/>
            <inertia ixx="8.33333333333e-05" ixy="0.0" ixz="0.0" iyy="8.33333333333e-05" iyz="0.0" izz="0.000125"/>
        </inertial>
    </link>
    
    <joint name="Ibeo_Offset" type="fixed">
        <origin rpy="-1.57079632679 0 -3.14159265359" xyz="-0.133 0.0065 -0.02325"/>
        <axis xyz="0 0 1"/>
        <parent link="Head"/>
        <child link="Ibeo_Frame"/>
    </joint>
    <link name="Ensenso_Frame">
        <!-- Virtual Link -->
        <inertial>
            <mass value="0.1"/>
            <origin rpy="0 0 0" xyz="0 0 0"/>
            <inertia ixx="8.33333333333e-05" ixy="0.0" ixz="0.0" iyy="8.33333333333e-05" iyz="0.0" izz="0.000125"/>
        </inertial>
    </link>
    <joint name="Ensenso_Offset" type="fixed">
        <origin rpy="0 -1.57079632679 0" xyz="-.1836 -.0645 -.00311"/>
        <axis xyz="0 0 1"/>
        <parent link="Head"/>
        <child link="Ensenso_Frame"/>
    </joint>
    <link name="EnsensoIR_Frame">
        <!-- Virtual Link -->
        <inertial>
            <mass value="0.1"/>
            <origin rpy="0 0 0" xyz="0 0 0"/>
            <inertia ixx="8.33333333333e-05" ixy="0.0" ixz="0.0" iyy="8.33333333333e-05" iyz="0.0" izz="0.000125"/>
        </inertial>
    </link>
    <joint name="EnsensoIR_Offset" type="fixed">
        <origin rpy="-0.31182 0.0562965 -0.0034575" xyz="0.0 0.006939 0.014954"/>
        <axis xyz="0 0 1"/>
        <parent link="Ensenso_Frame"/>
        <child link="EnsensoIR_Frame"/>
    </joint>
    <link name="HeadIMU_Frame">
        <inertial>
            <mass value="0.018"/>
            <origin rpy="0 0 0" xyz="0 0 0"/>
            <inertia ixx="3.0855e-06" ixy="0.0" ixz="0.0" iyy="3.768e-06" iyz="0.0" izz="1.0455e-06"/>
        </inertial>
        
        
    </link>
    
    <joint name="HeadIMU_Offset" type="fixed">
        <origin rpy="-1.57079632679 0  0" xyz="-0.103 -0.05239 0.00022730"/>
        <axis xyz="0 0 1"/>
        <parent link="Head"/>
        <child link="HeadIMU_Frame"/>
    </joint>
    <link name="HeadWebcam_Frame">
        <!-- Virtual Link -->
        <inertial>
            <mass value="0.1"/>
            <origin rpy="0 0 0" xyz="0 0 0"/>
            <inertia ixx="8.33333333333e-05" ixy="0.0" ixz="0.0" iyy="8.33333333333e-05" iyz="0.0" izz="0.000125"/>
        </inertial>
    </link>
    
    <joint name="HeadWebcam_Offset" type="fixed">
        <origin rpy="1.57079632679 3.14159265359 -0.2618" xyz="-0.180139 -0.10168 0.00"/>
        <axis xyz="0 0 1"/>
        <parent link="Head"/>
        <child link="HeadWebcam_Frame"/>
    </joint>
    <link name="RightShoulderExtensor">
        <inertial>
            <mass value="2.65"/>
            <origin rpy="0 0 0" xyz="0 -0.01204 -0.251"/>
            <inertia ixx="0.0137181666667" ixy="0.0" ixz="0.0" iyy="0.0105028333333" iyz="0.0" izz="0.0148064333333"/>
        </inertial>
        
        
    <collision><geometry><cylinder length="0.2" radius="0.08"/></geometry><origin rpy="1.57079632679 0 3.14159265359" xyz="0 -0.01 -0.246"/></collision><visual><geometry><cylinder length="0.2" radius="0.08"/></geometry><origin rpy="1.57079632679 0 3.14159265359" xyz="0 -0.01 -0.246"/><material name="Gold"/></visual></link>
    
    <link name="RightShoulderAdductor">
        <inertial>
            <mass value="2.87"/>
            <origin rpy="0 0 0" xyz="0.040 0.005 -0.02"/>
            <inertia ixx="0.0122024325" ixy="0.0" ixz="0.0" iyy="0.0175559325" iyz="0.0" izz="0.018176745"/>
        </inertial>
        
        
    <collision><geometry><cylinder length="0.12" radius="0.075"/></geometry><origin rpy="0 1.57079632679 0" xyz="0.07 0 0"/></collision><visual><geometry><cylinder length="0.12" radius="0.075"/></geometry><origin rpy="0 1.57079632679 0" xyz="0.07 0 0"/><material name="White"/></visual></link>
    
    <link name="RightShoulderRotator">
        <inertial>
            <mass value="2.575"/>
            <origin rpy="0 0 0" xyz="0.02 -0.004 -0.273"/>
            <inertia ixx="0.0227863895833" ixy="0.0" ixz="0.0" iyy="0.0213984645833" iyz="0.0" izz="0.00932579166667"/>
        </inertial>
        
        
    <collision><geometry><cylinder length="0.20" radius="0.075"/></geometry><origin rpy="0 0 0" xyz="0 0 -0.2"/></collision><visual><geometry><cylinder length="0.20" radius="0.075"/></geometry><origin rpy="0 0 0" xyz="0 0 -0.2"/><material name="White"/></visual></link>
    
    <link name="RightElbowExtensor">
        <inertial>
            <mass value="2.367"/>
            <origin rpy="0 0 0" xyz="0.0270 -0.0802 0"/>
            <inertia ixx="0.004941705" ixy="0.0" ixz="0.0" iyy="0.00469849291667" iyz="0.0" izz="0.00530133991667"/>
        </inertial>
        
        
    <collision><geometry><cylinder length="0.10" radius="0.06"/></geometry><origin rpy="0 0 0" xyz="0.02 -0.015 0"/></collision><visual><geometry><cylinder length="0.10" radius="0.06"/></geometry><origin rpy="0 0 0" xyz="0.02 -0.015 0"/><material name="Gold"/></visual></link>
    
    <joint name="RightShoulderExtensor" type="revolute">
        <origin rpy="1.57079632679 0 0" xyz="0.29842 0 -0.03157"/>
        <axis xyz="0 0 1"/>
        <parent link="Trunk"/>
        <child link="RightShoulderExtensor"/>
        <limit effort="190" lower="-3.1415926518" upper="3.1415926518" velocity="5.89"/>
        <controller_gains Kd="400" Kp="20000"/>
        <dynamics damping="1.0" friction="0.0"/>
    </joint>
    
    <joint name="RightShoulderAdductor" type="revolute">
        <origin rpy="1.57079632679 0 3.14159265359" xyz="0 0 -0.246"/>
        <axis xyz="0 0 1"/>
        <parent link="RightShoulderExtensor"/>
        <child link="RightShoulderAdductor"/>
        <limit effort="190" lower="-3.05432618925" upper="-0.1745329251" velocity="5.89"/>
        <controller_gains Kd="400" Kp="20000"/>
        <dynamics damping="1.0" friction="0.0"/>
    </joint>
    
    <joint name="RightShoulderSupinator" type="revolute">
        <origin rpy="-1.57079632679 0 1.57079632679" xyz="0 0 0"/>
        <axis xyz="0 0 1"/>
        <parent link="RightShoulderAdductor"/>
        <child link="RightShoulderRotator"/>
        <limit effort="65" lower="-1.5707963259" upper="1.5707963259" velocity="11.5"/>
        <controller_gains Kd="400" Kp="20000"/>
        <dynamics damping="1.0" friction="0.0"/>
    </joint>
    
    <joint name="RightElbowExtensor" type="revolute">
        <origin rpy="1.57079632679 0 1.57079632679" xyz="0 -0.0254 -0.33"/>
        <axis xyz="0 0 1"/>
        <parent link="RightShoulderRotator"/>
        <child link="RightElbowExtensor"/>
        <limit effort="65" lower="-1.9198621761" upper="-0.08726646255" velocity="11.5"/>
        <controller_gains Kd="400" Kp="20000"/>
        <dynamics damping="1.0" friction="0.0"/>
    </joint>
    
    <link name="RightForearm">
        <inertial>
            <mass value="2.703"/>
            <origin rpy="0 0 0" xyz="0 0.0006 -0.12"/>
            <inertia ixx="0.01633175125" ixy="0.0" ixz="0.0" iyy="0.0169338445" iyz="0.0" izz="0.00666402125"/>
        </inertial>
        
        
    <collision><geometry><cylinder length="0.22" radius="0.06"/></geometry><origin rpy="0 0 0" xyz="0 0 -0.17"/></collision><visual><geometry><cylinder length="0.22" radius="0.06"/></geometry><origin rpy="0 0 0" xyz="0 0 -0.17"/><material name="White"/></visual></link>
    
    <link name="RightWristYoke">
        <inertial>
            <mass value="0.1"/>
            <origin rpy="0 0 0" xyz="0 0 0"/>
            <inertia ixx="2.25083333333e-05" ixy="0.0" ixz="0.0" iyy="2.9175e-05" iyz="0.0" izz="8.33333333333e-06"/>
        </inertial>
        
        
    </link>
    <link name="RightPalm">
        <inertial>
            <mass value="0.712"/>
            <origin rpy="0 0 0" xyz="0.0425 0 0"/>
            <inertia ixx="0.000679010666667" ixy="0.0" ixz="0.0" iyy="0.000514360666667" iyz="0.0" izz="0.00102201666667"/>
        </inertial>
        
        
    <collision><geometry><box size="0.12 0.1 0.03"/></geometry><origin rpy="0 0 0" xyz="0.048 0 -0.0225"/><material name="White"/></collision><collision><geometry><box size="0.07 0.1 0.025"/></geometry><origin rpy="0 0 0" xyz="0.045 0 0.005"/><material name="White"/></collision><visual><geometry><box size="0.12 0.1 0.03"/></geometry><origin rpy="0 0 0" xyz="0.048 0 -0.0225"/><material name="White"/></visual><visual><geometry><box size="0.07 0.1 0.025"/></geometry><origin rpy="0 0 0" xyz="0.045 0 0.005"/><material name="White"/></visual></link>
    
    <joint name="RightForearmSupinator" type="revolute">
        <origin rpy="1.57079632679 0 3.14159265359" xyz="0.0254 0 0"/>
        <axis xyz="0 0 1"/>
        <parent link="RightElbowExtensor"/>
        <child link="RightForearm"/>
        <limit effort="26" lower="-2.35619448885" upper="2.35619448885" velocity="5"/>
        <controller_gains Kd="0" Kp="20000"/>
        <dynamics damping="1.0" friction="0.0"/>
    </joint>
    
    <joint name="RightWristExtensor" type="revolute">
        <origin rpy="-1.57079632679 0 1.57079632679" xyz="0 0 -0.287"/>
        <axis xyz="0 0 1"/>
        <parent link="RightForearm"/>
        <child link="RightWristYoke"/>
        <limit effort="14" lower="-0.8726646255" upper="0.6981317004" velocity="1"/>
        <controller_gains Kd="400" Kp="20000"/>
        <dynamics damping="1.0" friction="0.0"/>
    </joint>
    
    <joint name="RightWrist" type="revolute">
        <origin rpy="1.57079632679 0 1.57079632679" xyz="0 0 0"/>
        <axis xyz="0 0 1"/>
        <parent link="RightWristYoke"/>
        <child link="RightPalm"/>
        <limit effort="14" lower="-0.5235987753" upper="0.43633231275" velocity="1"/>
        <controller_gains Kd="400" Kp="20000"/>
        <dynamics damping="1.0" friction="0.0"/>
    </joint>
    
    
    
    
    
    
    
    
    
    
    
    
    
    
    
    <link name="RightCamBoard_Frame">
        <!-- Virtual Link -->
        <inertial>
            <mass value="0.1"/>
            <origin rpy="0 0 0" xyz="0 0 0"/>
            <inertia ixx="8.33333333333e-05" ixy="0.0" ixz="0.0" iyy="8.33333333333e-05" iyz="0.0" izz="0.000125"/>
        </inertial>
    </link>
    
    <joint name="RightCamBoard_Offset" type="fixed">
        <origin rpy="3.14159265359 1.57079632679 3.14159265359" xyz="0.049237 0.006877 -0.250708"/>
        <axis xyz="0 0 1"/>
        <parent link="RightForearm"/>
        <child link="RightCamBoard_Frame"/>
    </joint>
    <link name="RightCamBoardIR_Frame">
        <!-- Virtual Link -->
        <inertial>
            <mass value="0.1"/>
            <origin rpy="0 0 0" xyz="0 0 0"/>
            <inertia ixx="8.33333333333e-05" ixy="0.0" ixz="0.0" iyy="8.33333333333e-05" iyz="0.0" izz="0.000125"/>
        </inertial>
    </link>
    <joint name="RightCamBoardIR_Offset" type="fixed">
        <origin rpy="-1.4279169 0.057186 -1.603747" xyz="-0.05180 -0.0013 0.030237"/>
        <axis xyz="0 0 1"/>
        <parent link="RightCamBoard_Frame"/>
        <child link="RightCamBoardIR_Frame"/>
    </joint>
    <link name="LeftCamBoard_Frame">
        <!-- Virtual Link -->
        <inertial>
            <mass value="0.1"/>
            <origin rpy="0 0 0" xyz="0 0 0"/>
            <inertia ixx="8.33333333333e-05" ixy="0.0" ixz="0.0" iyy="8.33333333333e-05" iyz="0.0" izz="0.000125"/>
        </inertial>
    </link>
    
    <joint name="LeftCamBoard_Offset" type="fixed">
        <origin rpy="3.14159265359 -1.57079632679 0" xyz="0.045536 -0.0085 0.250708"/>
        <axis xyz="0 0 1"/>
        <parent link="LeftForearm"/>
        <child link="LeftCamBoard_Frame"/>
    </joint>
    <link name="LeftCamBoardIR_Frame">
        <!-- Virtual Link -->
        <inertial>
            <mass value="0.1"/>
            <origin rpy="0 0 0" xyz="0 0 0"/>
            <inertia ixx="8.33333333333e-05" ixy="0.0" ixz="0.0" iyy="8.33333333333e-05" iyz="0.0" izz="0.000125"/>
        </inertial>
    </link>
    <joint name="LeftCamBoardIR_Offset" type="fixed">
        <origin rpy="-1.4279169 0.057186 -1.603747" xyz="-0.05180 -0.0013 0.030237"/>
        <axis xyz="0 0 1"/>
        <parent link="LeftCamBoard_Frame"/>
        <child link="LeftCamBoardIR_Frame"/>
    </joint>
    <link name="RightThumbMetacarpal">
        <inertial>
            <mass value="0.017"/>
            <origin rpy="0 0 0" xyz="0 0 0"/>
            <inertia ixx="2.83333333333e-07" ixy="0.0" ixz="0.0" iyy="2.83333333333e-07" iyz="0.0" izz="2.83333333333e-07"/>
        </inertial>
        
        
    </link>
    
    <link name="RightThumbProximalPhalanx">
        <inertial>
            <mass value="0.02"/>
            <origin rpy="0 0 0" xyz="0.017 0 0"/>
            <inertia ixx="1.72833333333e-06" ixy="0.0" ixz="0.0" iyy="5.98666666667e-06" iyz="0.0" izz="5.46166666667e-06"/>
        </inertial>
        
        
    <collision><geometry><box size="0.04 0.015 0.025"/></geometry><origin rpy="0 0 0" xyz="0.02 0 0"/><material name="White"/></collision><visual><geometry><box size="0.04 0.015 0.025"/></geometry><origin rpy="0 0 0" xyz="0.02 0 0"/><material name="White"/></visual></link>
    
    <link name="RightThumbMedialPhalanx">
        <inertial>
            <mass value="0.013"/>
            <origin rpy="0 0 0" xyz="0.011 0 0"/>
            <inertia ixx="7.07416666667e-07" ixy="0.0" ixz="0.0" iyy="1.77666666667e-06" iyz="0.0" izz="1.43541666667e-06"/>
        </inertial>
        
        
    <collision><geometry><box size="0.03 0.015 0.020"/></geometry><origin rpy="0 0 0" xyz="0.015 0 0"/><material name="White"/></collision><visual><geometry><box size="0.03 0.015 0.020"/></geometry><origin rpy="0 0 0" xyz="0.015 0 0"/><material name="White"/></visual></link>
    
    <link name="RightThumbDistalPhalanx">
        <inertial>
            <mass value="0.006"/>
            <origin rpy="0 0 0" xyz="0.0086 0 0"/>
            <inertia ixx="2.525e-07" ixy="0.0" ixz="0.0" iyy="5.45e-07" iyz="0.0" izz="4.365e-07"/>
        </inertial>
        
        
    <collision><geometry><box size="0.022 0.015 0.017"/></geometry><origin rpy="0 0 0" xyz="0.011 0 0"/><material name="White"/></collision><visual><geometry><box size="0.022 0.015 0.017"/></geometry><origin rpy="0 0 0" xyz="0.011 0 0"/><material name="White"/></visual></link>
    
    <joint name="RightThumbMPYaw" type="fixed">
        <origin rpy="1.57079632679 0 -1.34390352" xyz="0.00748367180673 -0.0324153432851 0.005182"/>
        <axis xyz="0 0 1"/>
        <parent link="RightPalm"/>
        <child link="RightThumbMetacarpal"/>
    </joint>
    <joint name="RightThumbMPExtensor" type="fixed">
        <origin rpy="1.57079632679 0 0" xyz="0.02286 0 -0.025091"/>
        <axis xyz="0 0 1"/>
        <parent link="RightThumbMetacarpal"/>
        <child link="RightThumbProximalPhalanx"/>
    </joint>
    <joint name="RightThumbPIPExtensor" type="fixed">
        <origin rpy="0 0 0" xyz="0.0381 0 0"/>
        <axis xyz="0 0 1"/>
        <parent link="RightThumbProximalPhalanx"/>
        <child link="RightThumbMedialPhalanx"/>
    </joint>
    <joint name="RightThumbDIPExtensor" type="fixed">
        <origin rpy="0 0 0" xyz="0.02794 0 0"/>
        <axis xyz="0 0 1"/>
        <parent link="RightThumbMedialPhalanx"/>
        <child link="RightThumbDistalPhalanx"/>
    </joint>
    <link name="RightPrimaryMetacarpal">
        <inertial>
            <mass value="0.006"/>
            <origin rpy="0 0 0" xyz="-0.0048 0 0"/>
            <inertia ixx="4.225e-07" ixy="0.0" ixz="0.0" iyy="6.625e-07" iyz="0.0" izz="6.01e-07"/>
        </inertial>
        
        
    </link>
    
    <link name="RightPrimaryProximalPhalanx">
        <inertial>
            <mass value="0.018"/>
            <origin rpy="0 0 0" xyz="0.0175 0 0"/>
            <inertia ixx="1.203e-06" ixy="0.0" ixz="0.0" iyy="5.0355e-06" iyz="0.0" izz="4.9155e-06"/>
        </inertial>
        
        
    <collision><geometry><box size="0.04 0.015 0.025"/></geometry><origin rpy="0 0 0" xyz="0.02 0 0"/><material name="White"/></collision><visual><geometry><box size="0.04 0.015 0.025"/></geometry><origin rpy="0 0 0" xyz="0.02 0 0"/><material name="White"/></visual></link>
    
    <link name="RightPrimaryMedialPhalanx">
        <inertial>
            <mass value="0.01"/>
            <origin rpy="0 0 0" xyz="0.0108 -0.0003 0"/>
            <inertia ixx="3.81666666667e-07" ixy="0.0" ixz="0.0" iyy="1.20416666667e-06" iyz="0.0" izz="1.10416666667e-06"/>
        </inertial>
        
        
    <collision><geometry><box size="0.03 0.015 0.020"/></geometry><origin rpy="0 0 0" xyz="0.015 0 0"/><material name="White"/></collision><visual><geometry><box size="0.03 0.015 0.020"/></geometry><origin rpy="0 0 0" xyz="0.015 0 0"/><material name="White"/></visual></link>
    
    <link name="RightPrimaryDistalPhalanx">
        <inertial>
            <mass value="0.005"/>
            <origin rpy="0 0 0" xyz="0.00857 -0.000696 0"/>
            <inertia ixx="1.5375e-07" ixy="0.0" ixz="0.0" iyy="3.975e-07" iyz="0.0" izz="3.6375e-07"/>
        </inertial>
        
        
    <collision><geometry><box size="0.022 0.015 0.017"/></geometry><origin rpy="0 0 0" xyz="0.011 0 0"/><material name="White"/></collision><visual><geometry><box size="0.022 0.015 0.017"/></geometry><origin rpy="0 0 0" xyz="0.011 0 0"/><material name="White"/></visual></link>
    
    <joint name="RightPrimaryMPYaw" type="fixed">
        <origin rpy="0.0 0 -0.366519143" xyz="0.0776738914821 -0.0298162134085 0.00254"/>
        <axis xyz="0 0 1"/>
        <parent link="RightPalm"/>
        <child link="RightPrimaryMetacarpal"/>
    </joint>
    <joint name="RightPrimaryMPExtensor" type="fixed">
        <origin rpy="-1.57079632679 0 0.0568977336" xyz="0.0169724899301 0.000966739661347 0"/>
        <axis xyz="0 0 1"/>
        <parent link="RightPrimaryMetacarpal"/>
        <child link="RightPrimaryProximalPhalanx"/>
    </joint>
    <joint name="RightPrimaryPIPExtensor" type="fixed">
        <origin rpy="0 0 0" xyz="0.0381 0 0"/>
        <axis xyz="0 0 1"/>
        <parent link="RightPrimaryProximalPhalanx"/>
        <child link="RightPrimaryMedialPhalanx"/>
    </joint>
    <joint name="RightPrimaryDIPExtensor" type="fixed">
        <origin rpy="0 0 0" xyz="0.02286 0 0"/>
        <axis xyz="0 0 1"/>
        <parent link="RightPrimaryMedialPhalanx"/>
        <child link="RightPrimaryDistalPhalanx"/>
    </joint>
    <link name="RightMiddleProximalPhalanx">
        <inertial>
            <mass value="0.02"/>
            <origin rpy="0 0 0" xyz="0.017 0 0"/>
            <inertia ixx="1.72833333333e-06" ixy="0.0" ixz="0.0" iyy="5.98666666667e-06" iyz="0.0" izz="5.46166666667e-06"/>
        </inertial>
        
        
    <collision><geometry><box size="0.04 0.015 0.025"/></geometry><origin rpy="0 0 0" xyz="0.02 0 0"/><material name="White"/></collision><visual><geometry><box size="0.04 0.015 0.025"/></geometry><origin rpy="0 0 0" xyz="0.02 0 0"/><material name="White"/></visual></link>
    
    <link name="RightMiddleMedialPhalanx">
        <inertial>
            <mass value="0.011"/>
            <origin rpy="0 0 0" xyz="0.011 0 0"/>
            <inertia ixx="5.98583333333e-07" ixy="0.0" ixz="0.0" iyy="1.50333333333e-06" iyz="0.0" izz="1.21458333333e-06"/>
        </inertial>
        
        
    <collision><geometry><box size="0.03 0.015 0.020"/></geometry><origin rpy="0 0 0" xyz="0.015 0 0"/><material name="White"/></collision><visual><geometry><box size="0.03 0.015 0.020"/></geometry><origin rpy="0 0 0" xyz="0.015 0 0"/><material name="White"/></visual></link>
    
    <link name="RightMiddleDistalPhalanx">
        <inertial>
            <mass value="0.006"/>
            <origin rpy="0 0 0" xyz="0.0086 0 0"/>
            <inertia ixx="2.525e-07" ixy="0.0" ixz="0.0" iyy="5.45e-07" iyz="0.0" izz="4.365e-07"/>
        </inertial>
        
        
    <collision><geometry><box size="0.022 0.015 0.017"/></geometry><origin rpy="0 0 0" xyz="0.011 0 0"/><material name="White"/></collision><visual><geometry><box size="0.022 0.015 0.017"/></geometry><origin rpy="0 0 0" xyz="0.011 0 0"/><material name="White"/></visual></link>
    
    <joint name="RightMiddleMPExtensor" type="fixed">
        <origin rpy="-1.57079632679 0 0" xyz="0.09767 0 0.00254"/>
        <axis xyz="0 0 1"/>
        <parent link="RightPalm"/>
        <child link="RightMiddleProximalPhalanx"/>
    </joint>
    <joint name="RightMiddlePIPExtensor" type="fixed">
        <origin rpy="0 0 0" xyz="0.0381 0 0"/>
        <axis xyz="0 0 1"/>
        <parent link="RightMiddleProximalPhalanx"/>
        <child link="RightMiddleMedialPhalanx"/>
    </joint>
    <joint name="RightMiddleDIPExtensor" type="fixed">
        <origin rpy="0 0 0" xyz="0.02286 0 0"/>
        <axis xyz="0 0 1"/>
        <parent link="RightMiddleMedialPhalanx"/>
        <child link="RightMiddleDistalPhalanx"/>
    </joint>
    <link name="RightMedialMetacarpal">
        <inertial>
            <mass value="0.047"/>
            <origin rpy="0 0 0" xyz="0 0 0"/>
            <inertia ixx="7.83333333333e-07" ixy="0.0" ixz="0.0" iyy="7.83333333333e-07" iyz="0.0" izz="7.83333333333e-07"/>
        </inertial>
        
        
    </link>
    
    <link name="RightLittleProximalPhalanx">
        <inertial>
            <mass value="0.02"/>
            <origin rpy="0 0 0" xyz="0 0.017 0.050169"/>
            <inertia ixx="5.98666666667e-06" ixy="0.0" ixz="0.0" iyy="1.72833333333e-06" iyz="0.0" izz="5.46166666667e-06"/>
        </inertial>
        
        
    <collision><geometry><box size="0.04 0.015 0.025"/></geometry><origin rpy="0 0 1.57079632679" xyz="0 0.02 0.05"/><material name="White"/></collision><visual><geometry><box size="0.04 0.015 0.025"/></geometry><origin rpy="0 0 1.57079632679" xyz="0 0.02 0.05"/><material name="White"/></visual></link>
    
    <link name="RightLittleMedialPhalanx">
        <inertial>
            <mass value="0.011"/>
            <origin rpy="0 0 0" xyz="0.011 0 0"/>
            <inertia ixx="5.98583333333e-07" ixy="0.0" ixz="0.0" iyy="1.50333333333e-06" iyz="0.0" izz="1.21458333333e-06"/>
        </inertial>
        
        
    <collision><geometry><box size="0.03 0.015 0.020"/></geometry><origin rpy="0 0 0" xyz="0.015 0 0"/><material name="White"/></collision><visual><geometry><box size="0.03 0.015 0.020"/></geometry><origin rpy="0 0 0" xyz="0.015 0 0"/><material name="White"/></visual></link>
    
    <link name="RightLittleDistalPhalanx">
        <inertial>
            <mass value="0.006"/>
            <origin rpy="0 0 0" xyz="0.0086 0 0"/>
            <inertia ixx="2.525e-07" ixy="0.0" ixz="0.0" iyy="5.45e-07" iyz="0.0" izz="4.365e-07"/>
        </inertial>
        
        
    <collision><geometry><box size="0.022 0.015 0.017"/></geometry><origin rpy="0 0 0" xyz="0.011 0 0"/><material name="White"/></collision><visual><geometry><box size="0.022 0.015 0.017"/></geometry><origin rpy="0 0 0" xyz="0.011 0 0"/><material name="White"/></visual></link>
    
    <joint name="RightLittleMPYaw" type="fixed">
        <origin rpy="-1.57079632679 0 0.690626785" xyz="0.0427072303336 0.0352928446888 -0.007747"/>
        <axis xyz="0 0 1"/>
        <parent link="RightPalm"/>
        <child link="RightMedialMetacarpal"/>
    </joint>
    <joint name="RightLittleMPExtensor" type="fixed">
        <origin rpy="-0.690626785 0 -1.57079632679" xyz="0 -0.010287 -0.071327"/>
        <axis xyz="0 0 1"/>
        <parent link="RightMedialMetacarpal"/>
        <child link="RightLittleProximalPhalanx"/>
    </joint>
    <joint name="RightLittlePIPExtensor" type="fixed">
        <origin rpy="0 0 1.57079632679" xyz="0 0.0381 0.050169"/>
        <axis xyz="0 0 1"/>
        <parent link="RightLittleProximalPhalanx"/>
        <child link="RightLittleMedialPhalanx"/>
    </joint>
    <joint name="RightLittleDIPExtensor" type="fixed">
        <origin rpy="0 0 0" xyz="0.02286 0 0"/>
        <axis xyz="0 0 1"/>
        <parent link="RightLittleMedialPhalanx"/>
        <child link="RightLittleDistalPhalanx"/>
    </joint>
    <link name="LeftShoulderExtensor">
        <inertial>
            <mass value="2.65"/>
            <origin rpy="0 0 0" xyz="0 -0.01204 0.251"/>
            <inertia ixx="0.0137181666667" ixy="0.0" ixz="0.0" iyy="0.0105028333333" iyz="0.0" izz="0.0148064333333"/>
        </inertial>
        
        
    <collision><geometry><cylinder length="0.2" radius="0.08"/></geometry><origin rpy="1.57079632679 0 3.14159265359" xyz="0 -0.01 0.246"/></collision><visual><geometry><cylinder length="0.2" radius="0.08"/></geometry><origin rpy="1.57079632679 0 3.14159265359" xyz="0 -0.01 0.246"/><material name="Gold"/></visual></link>
    
    <link name="LeftShoulderAdductor">
        <inertial>
            <mass value="2.87"/>
            <origin rpy="0.0 0.00 0.0" xyz="0.04 0.005 0.02"/>
            <inertia ixx="0.0122024325" ixy="0.0" ixz="0.0" iyy="0.0175559325" iyz="0.0" izz="0.018176745"/>
        </inertial>
        
        
    <collision><geometry><cylinder length="0.12" radius="0.075"/></geometry><origin rpy="0 1.57079632679 0" xyz="0.07 0 0"/></collision><visual><geometry><cylinder length="0.12" radius="0.075"/></geometry><origin rpy="0 1.57079632679 0" xyz="0.07 0 0"/><material name="White"/></visual></link>
    
    <link name="LeftShoulderRotator">
        <inertial>
            <mass value="2.575"/>
            <origin rpy="0 0 0" xyz="-0.02 0.004 0.273"/>
            <inertia ixx="0.0227863895833" ixy="0.0" ixz="0.0" iyy="0.0213984645833" iyz="0.0" izz="0.00932579166667"/>
        </inertial>
        
        
    <collision><geometry><cylinder length="0.20" radius="0.075"/></geometry><origin rpy="0 0 0" xyz="0 0 0.2"/></collision><visual><geometry><cylinder length="0.20" radius="0.075"/></geometry><origin rpy="0 0 0" xyz="0 0 0.2"/><material name="White"/></visual></link>
    
    <link name="LeftElbowExtensor">
        <inertial>
            <mass value="2.367"/>
            <origin rpy="0 0 0" xyz="0.0270 -0.0802 0"/>
            <inertia ixx="0.004941705" ixy="0.0" ixz="0.0" iyy="0.00469849291667" iyz="0.0" izz="0.00530133991667"/>
        </inertial>
        
        
    <collision><geometry><cylinder length="0.10" radius="0.06"/></geometry><origin rpy="0 0 0" xyz="0.02 -0.015 0"/></collision><visual><geometry><cylinder length="0.10" radius="0.06"/></geometry><origin rpy="0 0 0" xyz="0.02 -0.015 0"/><material name="Gold"/></visual></link>
    
    <joint name="LeftShoulderExtensor" type="revolute">
        <origin rpy="1.57079632679 0 0" xyz="0.29842 0 -0.03157"/>
        <axis xyz="0 0 1"/>
        <parent link="Trunk"/>
        <child link="LeftShoulderExtensor"/>
        <limit effort="190" lower="-3.1415926518" upper="3.1415926518" velocity="5.89"/>
        <controller_gains Kd="400" Kp="20000"/>
        <dynamics damping="1.0" friction="0.0"/>
    </joint>
    
    <joint name="LeftShoulderAdductor" type="revolute">
        <origin rpy="-1.57079632679 0 3.14159265359" xyz="0 0 0.246"/>
        <axis xyz="0 0 1"/>
        <parent link="LeftShoulderExtensor"/>
        <child link="LeftShoulderAdductor"/>
        <limit effort="190" lower="-3.05432618925" upper="-0.1745329251" velocity="5.89"/>
        <controller_gains Kd="400" Kp="20000"/>
        <dynamics damping="1.0" friction="0.0"/>
    </joint>
    
    <joint name="LeftShoulderSupinator" type="revolute">
        <origin rpy="-1.57079632679 0 -1.57079632679" xyz="0 0 0"/>
        <axis xyz="0 0 1"/>
        <parent link="LeftShoulderAdductor"/>
        <child link="LeftShoulderRotator"/>
        <limit effort="65" lower="-1.5707963259" upper="1.5707963259" velocity="11.5"/>
        <controller_gains Kd="400" Kp="20000"/>
        <dynamics damping="1.0" friction="0.0"/>
    </joint>
    
    <joint name="LeftElbowExtensor" type="revolute">
        <origin rpy="-1.57079632679 0 -1.57079632679" xyz="0 0.0254 0.33"/>
        <axis xyz="0 0 1"/>
        <parent link="LeftShoulderRotator"/>
        <child link="LeftElbowExtensor"/>
        <limit effort="65" lower="-1.9198621761" upper="-0.08726646255" velocity="11.5"/>
        <controller_gains Kd="400" Kp="20000"/>
        <dynamics damping="1.0" friction="0.0"/>
    </joint>
    
    <link name="LeftForearm">
        <inertial>
            <mass value="2.703"/>
            <origin rpy="0 0 0" xyz="0 -0.0006 0.12"/>
            <inertia ixx="0.01633175125" ixy="0.0" ixz="0.0" iyy="0.0169338445" iyz="0.0" izz="0.00666402125"/>
        </inertial>
        
        
    <collision><geometry><cylinder length="0.22" radius="0.06"/></geometry><origin rpy="0 0 0" xyz="0 0 0.17"/></collision><visual><geometry><cylinder length="0.22" radius="0.06"/></geometry><origin rpy="0 0 0" xyz="0 0 0.17"/><material name="White"/></visual></link>
    
    <link name="LeftWristYoke">
        <inertial>
            <mass value="0.1"/>
            <origin rpy="0 0 0" xyz="0 0 0"/>
            <inertia ixx="2.25083333333e-05" ixy="0.0" ixz="0.0" iyy="2.9175e-05" iyz="0.0" izz="8.33333333333e-06"/>
        </inertial>
        
        
    </link>
    <link name="LeftPalm">
        <inertial>
            <mass value="0.712"/>
            <origin rpy="0 0 0" xyz="0.0425 0 0"/>
            <inertia ixx="0.000679010666667" ixy="0.0" ixz="0.0" iyy="0.000514360666667" iyz="0.0" izz="0.00102201666667"/>
        </inertial>
        
        
    <collision><geometry><box size="0.12 0.1 0.03"/></geometry><origin rpy="0 0 0" xyz="0.048 0 0.0225"/><material name="White"/></collision><collision><geometry><box size="0.07 0.1 0.025"/></geometry><origin rpy="0 0 0" xyz="0.045 0 -0.005"/><material name="White"/></collision><visual><geometry><box size="0.12 0.1 0.03"/></geometry><origin rpy="0 0 0" xyz="0.048 0 0.0225"/><material name="White"/></visual><visual><geometry><box size="0.07 0.1 0.025"/></geometry><origin rpy="0 0 0" xyz="0.045 0 -0.005"/><material name="White"/></visual></link>
    


  <!-- mfallon extra stuff left hand-->
  <link name="l_hand_force_torque">
    <inertial>
      <mass value="0.001"/>
      <origin xyz="0 0 0"/>
      <inertia ixx="0.00001" ixy="0" ixz="0" iyy="0.00001" iyz="0" izz="0.00001"/>
    </inertial>
    
  </link>
  <joint name="l_hand_force_torque_joint" type="fixed">
    <origin rpy="0 0 0" xyz="0 0 0"/>
    <parent link="LeftPalm"/>
    <child link="l_hand_force_torque"/>
  </joint>
  <link name="left_palm">
    <inertial>
      <mass value="0.001"/>
      <origin xyz="0 0 0"/>
      <inertia ixx="0.00001" ixy="0" ixz="0" iyy="0.00001" iyz="0" izz="0.00001"/>
    </inertial>
    
  </link>
  <joint name="left_valkyrie_hand_joint" type="fixed">
    <origin rpy="1.57079632679 1.57079632679 0" xyz="0.08 0 0"/>
    <parent link="l_hand_force_torque"/>
    <child link="left_palm"/>
  </joint>
  <link name="l_hand_face">
    <inertial>
      <mass value="0.001"/>
      <origin xyz="0 0 0"/>
      <inertia ixx="0.00001" ixy="0" ixz="0" iyy="0.00001" iyz="0" izz="0.00001"/>
    </inertial>
  </link>
  <joint name="l_hand_face_joint" type="fixed">
    <origin rpy="3.14159265359 0 1.57079632679" xyz="0.08 0.0 -0.04"/>
    <parent link="l_hand_force_torque"/>
    <child link="l_hand_face"/>
  </joint>
  <!-- end mfallon extra stuff left hand-->




  <!-- mfallon extra stuff right hand-->
  <link name="r_hand_force_torque">
    <inertial>
      <mass value="0.001"/>
      <origin xyz="0 0 0"/>
      <inertia ixx="0.00001" ixy="0" ixz="0" iyy="0.00001" iyz="0" izz="0.00001"/>
    </inertial>
    
  </link>
  <joint name="r_hand_force_torque_joint" type="fixed">
    <origin rpy="0 0 0" xyz="0 0 0"/>
    <parent link="RightPalm"/>
    <child link="r_hand_force_torque"/>
  </joint>
  <link name="right_palm">
    <inertial>
      <mass value="0.001"/>
      <origin xyz="0 0 0"/>
      <inertia ixx="0.00001" ixy="0" ixz="0" iyy="0.00001" iyz="0" izz="0.00001"/>
    </inertial>
    
  </link>
  <joint name="right_valkyrie_hand_joint" type="fixed">
    <origin rpy="0 -1.57079632679 -1.57079632679" xyz="0.08 0 0"/>
    <parent link="r_hand_force_torque"/>
    <child link="right_palm"/>
  </joint>
  <link name="r_hand_face">
    <inertial>
      <mass value="0.001"/>
      <origin xyz="0 0 0"/>
      <inertia ixx="0.00001" ixy="0" ixz="0" iyy="0.00001" iyz="0" izz="0.00001"/>
    </inertial>
  </link>
  <joint name="r_hand_face_joint" type="fixed">
    <origin rpy="0 0 -1.57079632679" xyz="0.08 0 0.04"/>
    <parent link="r_hand_force_torque"/>
    <child link="r_hand_face"/>
  </joint>
  <!-- end mfallon extra stuff right hand-->




    <joint name="LeftForearmSupinator" type="revolute">
        <origin rpy="-1.57079632679 0 3.14159265359" xyz="0.0254 0 0"/>
        <axis xyz="0 0 1"/>
        <parent link="LeftElbowExtensor"/>
        <child link="LeftForearm"/>
        <limit effort="26" lower="-2.35619448885" upper="2.35619448885" velocity="5"/>
        <controller_gains Kd="0" Kp="20000"/>
        <dynamics damping="1.0" friction="0.0"/>
    </joint>
    
    <joint name="LeftWristExtensor" type="revolute">
        <origin rpy="-1.57079632679 0 -1.57079632679" xyz="0 0 0.287"/>
        <axis xyz="0 0 1"/>
        <parent link="LeftForearm"/>
        <child link="LeftWristYoke"/>
        <limit effort="14" lower="-0.8726646255" upper="0.6981317004" velocity="1"/>
        <controller_gains Kd="400" Kp="20000"/>
        <dynamics damping="1.0" friction="0.0"/>
    </joint>
    
    <joint name="LeftWrist" type="revolute">
        <origin rpy="-1.57079632679 0 -1.57079632679" xyz="0 0 0"/>
        <axis xyz="0 0 1"/>
        <parent link="LeftWristYoke"/>
        <child link="LeftPalm"/>
        <limit effort="14" lower="-0.5235987753" upper="0.43633231275" velocity="1"/>
        <controller_gains Kd="400" Kp="20000"/>
        <dynamics damping="1.0" friction="0.0"/>
    </joint>
    
    
    
    
    
    
    
    
    
    
    
    
    
    
    
    <link name="LeftThumbMetacarpal">
        <inertial>
            <mass value="0.017"/>
            <origin rpy="0 0 0" xyz="0 0 0"/>
            <inertia ixx="2.83333333333e-07" ixy="0.0" ixz="0.0" iyy="2.83333333333e-07" iyz="0.0" izz="2.83333333333e-07"/>
        </inertial>
        
        
    </link>
    
    <link name="LeftThumbProximalPhalanx">
        <inertial>
            <mass value="0.02"/>
            <origin rpy="0 0 0" xyz="0.017 0 0"/>
            <inertia ixx="1.72833333333e-06" ixy="0.0" ixz="0.0" iyy="5.98666666667e-06" iyz="0.0" izz="5.46166666667e-06"/>
        </inertial>
        
        
    <collision><geometry><box size="0.04 0.015 0.025"/></geometry><origin rpy="0 0 0" xyz="0.02 0 0"/><material name="White"/></collision><visual><geometry><box size="0.04 0.015 0.025"/></geometry><origin rpy="0 0 0" xyz="0.02 0 0"/><material name="White"/></visual></link>
    
    <link name="LeftThumbMedialPhalanx">
        <inertial>
            <mass value="0.013"/>
            <origin rpy="0 0 0" xyz="0.011 0 0"/>
            <inertia ixx="7.07416666667e-07" ixy="0.0" ixz="0.0" iyy="1.77666666667e-06" iyz="0.0" izz="1.43541666667e-06"/>
        </inertial>
        
        
    <collision><geometry><box size="0.03 0.015 0.020"/></geometry><origin rpy="0 0 0" xyz="0.015 0 0"/><material name="White"/></collision><visual><geometry><box size="0.03 0.015 0.020"/></geometry><origin rpy="0 0 0" xyz="0.015 0 0"/><material name="White"/></visual></link>
    
    <link name="LeftThumbDistalPhalanx">
        <inertial>
            <mass value="0.006"/>
            <origin rpy="0 0 0" xyz="0.0086 0 0"/>
            <inertia ixx="2.525e-07" ixy="0.0" ixz="0.0" iyy="5.45e-07" iyz="0.0" izz="4.365e-07"/>
        </inertial>
        
        
    <collision><geometry><box size="0.022 0.015 0.017"/></geometry><origin rpy="0 0 0" xyz="0.011 0 0"/><material name="White"/></collision><visual><geometry><box size="0.022 0.015 0.017"/></geometry><origin rpy="0 0 0" xyz="0.011 0 0"/><material name="White"/></visual></link>
    
    <joint name="LeftThumbMPYaw" type="fixed">
        <origin rpy="-1.57079632679 0 -1.34390352" xyz="0.00748367180673 -0.0324153432851 -0.005182"/>
        <axis xyz="0 0 1"/>
        <parent link="LeftPalm"/>
        <child link="LeftThumbMetacarpal"/>
    </joint>
    <joint name="LeftThumbMPExtensor" type="fixed">
        <origin rpy="-1.57079632679 0 0" xyz="0.02286 0 0.025091"/>
        <axis xyz="0 0 1"/>
        <parent link="LeftThumbMetacarpal"/>
        <child link="LeftThumbProximalPhalanx"/>
    </joint>
    <joint name="LeftThumbPIPExtensor" type="fixed">
        <origin rpy="0 0 0" xyz="0.0381 0 0"/>
        <axis xyz="0 0 1"/>
        <parent link="LeftThumbProximalPhalanx"/>
        <child link="LeftThumbMedialPhalanx"/>
    </joint>
    <joint name="LeftThumbDIPExtensor" type="fixed">
        <origin rpy="0 0 0" xyz="0.02794 0 0"/>
        <axis xyz="0 0 1"/>
        <parent link="LeftThumbMedialPhalanx"/>
        <child link="LeftThumbDistalPhalanx"/>
    </joint>
    <link name="LeftPrimaryMetacarpal">
        <inertial>
            <mass value="0.006"/>
            <origin rpy="0 0 0" xyz="-0.0048 0 0"/>
            <inertia ixx="4.225e-07" ixy="0.0" ixz="0.0" iyy="6.625e-07" iyz="0.0" izz="6.01e-07"/>
        </inertial>
        
        
    </link>
    
    <link name="LeftPrimaryProximalPhalanx">
        <inertial>
            <mass value="0.018"/>
            <origin rpy="0 0 0" xyz="0.0175 0 0"/>
            <inertia ixx="1.203e-06" ixy="0.0" ixz="0.0" iyy="5.0355e-06" iyz="0.0" izz="4.9155e-06"/>
        </inertial>
        
        
    <collision><geometry><box size="0.04 0.015 0.025"/></geometry><origin rpy="0 0 0" xyz="0.02 0 0"/><material name="White"/></collision><visual><geometry><box size="0.04 0.015 0.025"/></geometry><origin rpy="0 0 0" xyz="0.02 0 0"/><material name="White"/></visual></link>
    
    <link name="LeftPrimaryMedialPhalanx">
        <inertial>
            <mass value="0.01"/>
            <origin rpy="0 0 0" xyz="0.0108 -0.0003 0"/>
            <inertia ixx="3.81666666667e-07" ixy="0.0" ixz="0.0" iyy="1.20416666667e-06" iyz="0.0" izz="1.10416666667e-06"/>
        </inertial>
        
        
    <collision><geometry><box size="0.03 0.015 0.020"/></geometry><origin rpy="0 0 0" xyz="0.015 0 0"/><material name="White"/></collision><visual><geometry><box size="0.03 0.015 0.020"/></geometry><origin rpy="0 0 0" xyz="0.015 0 0"/><material name="White"/></visual></link>
    
    <link name="LeftPrimaryDistalPhalanx">
        <inertial>
            <mass value="0.005"/>
            <origin rpy="0 0 0" xyz="0.00857 -0.000696 0"/>
            <inertia ixx="1.5375e-07" ixy="0.0" ixz="0.0" iyy="3.975e-07" iyz="0.0" izz="3.6375e-07"/>
        </inertial>
        
        
    <collision><geometry><box size="0.022 0.015 0.017"/></geometry><origin rpy="0 0 0" xyz="0.011 0 0"/><material name="White"/></collision><visual><geometry><box size="0.022 0.015 0.017"/></geometry><origin rpy="0 0 0" xyz="0.011 0 0"/><material name="White"/></visual></link>
    
    <joint name="LeftPrimaryMPYaw" type="fixed">
        <origin rpy="-3.14159265359 0 -0.366519143" xyz="0.0776738914821 -0.0298162134085 -0.00254"/>
        <axis xyz="0 0 1"/>
        <parent link="LeftPalm"/>
        <child link="LeftPrimaryMetacarpal"/>
    </joint>
    <joint name="LeftPrimaryMPExtensor" type="fixed">
        <origin rpy="-1.57079632679 0 0.0568977336" xyz="0.0169724899301 0.000966739661347 0"/>
        <axis xyz="0 0 1"/>
        <parent link="LeftPrimaryMetacarpal"/>
        <child link="LeftPrimaryProximalPhalanx"/>
    </joint>
    <joint name="LeftPrimaryPIPExtensor" type="fixed">
        <origin rpy="0 0 0" xyz="0.0381 0 0"/>
        <axis xyz="0 0 1"/>
        <parent link="LeftPrimaryProximalPhalanx"/>
        <child link="LeftPrimaryMedialPhalanx"/>
    </joint>
    <joint name="LeftPrimaryDIPExtensor" type="fixed">
        <origin rpy="0 0 0" xyz="0.02286 0 0"/>
        <axis xyz="0 0 1"/>
        <parent link="LeftPrimaryMedialPhalanx"/>
        <child link="LeftPrimaryDistalPhalanx"/>
    </joint>
    <link name="LeftMiddleProximalPhalanx">
        <inertial>
            <mass value="0.02"/>
            <origin rpy="0 0 0" xyz="0.017 0 0"/>
            <inertia ixx="1.72833333333e-06" ixy="0.0" ixz="0.0" iyy="5.98666666667e-06" iyz="0.0" izz="5.46166666667e-06"/>
        </inertial>
        
        
    <collision><geometry><box size="0.04 0.015 0.025"/></geometry><origin rpy="0 0 0" xyz="0.02 0 0"/><material name="White"/></collision><visual><geometry><box size="0.04 0.015 0.025"/></geometry><origin rpy="0 0 0" xyz="0.02 0 0"/><material name="White"/></visual></link>
    
    <link name="LeftMiddleMedialPhalanx">
        <inertial>
            <mass value="0.011"/>
            <origin rpy="0 0 0" xyz="0.011 0 0"/>
            <inertia ixx="5.98583333333e-07" ixy="0.0" ixz="0.0" iyy="1.50333333333e-06" iyz="0.0" izz="1.21458333333e-06"/>
        </inertial>
        
        
    <collision><geometry><box size="0.03 0.015 0.020"/></geometry><origin rpy="0 0 0" xyz="0.015 0 0"/><material name="White"/></collision><visual><geometry><box size="0.03 0.015 0.020"/></geometry><origin rpy="0 0 0" xyz="0.015 0 0"/><material name="White"/></visual></link>
    
    <link name="LeftMiddleDistalPhalanx">
        <inertial>
            <mass value="0.006"/>
            <origin rpy="0 0 0" xyz="0.0086 0 0"/>
            <inertia ixx="2.525e-07" ixy="0.0" ixz="0.0" iyy="5.45e-07" iyz="0.0" izz="4.365e-07"/>
        </inertial>
        
        
    <collision><geometry><box size="0.022 0.015 0.017"/></geometry><origin rpy="0 0 0" xyz="0.011 0 0"/><material name="White"/></collision><visual><geometry><box size="0.022 0.015 0.017"/></geometry><origin rpy="0 0 0" xyz="0.011 0 0"/><material name="White"/></visual></link>
    
    <joint name="LeftMiddleMPExtensor" type="fixed">
        <origin rpy="1.57079632679 0 0" xyz="0.09767 0 -0.00254"/>
        <axis xyz="0 0 1"/>
        <parent link="LeftPalm"/>
        <child link="LeftMiddleProximalPhalanx"/>
    </joint>
    <joint name="LeftMiddlePIPExtensor" type="fixed">
        <origin rpy="0 0 0" xyz="0.0381 0 0"/>
        <axis xyz="0 0 1"/>
        <parent link="LeftMiddleProximalPhalanx"/>
        <child link="LeftMiddleMedialPhalanx"/>
    </joint>
    <joint name="LeftMiddleDIPExtensor" type="fixed">
        <origin rpy="0 0 0" xyz="0.02286 0 0"/>
        <axis xyz="0 0 1"/>
        <parent link="LeftMiddleMedialPhalanx"/>
        <child link="LeftMiddleDistalPhalanx"/>
    </joint>
    <link name="LeftMedialMetacarpal">
        <inertial>
            <mass value="0.047"/>
            <origin rpy="0 0 0" xyz="0 0 0"/>
            <inertia ixx="7.83333333333e-07" ixy="0.0" ixz="0.0" iyy="7.83333333333e-07" iyz="0.0" izz="7.83333333333e-07"/>
        </inertial>
        
        
    </link>
    
    <link name="LeftLittleProximalPhalanx">
        <inertial>
            <mass value="0.02"/>
            <origin rpy="0 0 0" xyz="0 -0.017 -0.050169"/>
            <inertia ixx="5.98666666667e-06" ixy="0.0" ixz="0.0" iyy="1.72833333333e-06" iyz="0.0" izz="5.46166666667e-06"/>
        </inertial>
        
        
    <collision><geometry><box size="0.04 0.015 0.025"/></geometry><origin rpy="0 0 -1.57079632679" xyz="0 -0.02 -0.05"/><material name="White"/></collision><visual><geometry><box size="0.04 0.015 0.025"/></geometry><origin rpy="0 0 -1.57079632679" xyz="0 -0.02 -0.05"/><material name="White"/></visual></link>
    
    <link name="LeftLittleMedialPhalanx">
        <inertial>
            <mass value="0.011"/>
            <origin rpy="0 0 0" xyz="0.011 0 0"/>
            <inertia ixx="5.98583333333e-07" ixy="0.0" ixz="0.0" iyy="1.50333333333e-06" iyz="0.0" izz="1.21458333333e-06"/>
        </inertial>
        
        
    <collision><geometry><box size="0.03 0.015 0.020"/></geometry><origin rpy="0 0 0" xyz="0.015 0 0"/><material name="White"/></collision><visual><geometry><box size="0.03 0.015 0.020"/></geometry><origin rpy="0 0 0" xyz="0.015 0 0"/><material name="White"/></visual></link>
    
    <link name="LeftLittleDistalPhalanx">
        <inertial>
            <mass value="0.006"/>
            <origin rpy="0 0 0" xyz="0.0086 0 0"/>
            <inertia ixx="2.525e-07" ixy="0.0" ixz="0.0" iyy="5.45e-07" iyz="0.0" izz="4.365e-07"/>
        </inertial>
        
        
    <collision><geometry><box size="0.022 0.015 0.017"/></geometry><origin rpy="0 0 0" xyz="0.011 0 0"/><material name="White"/></collision><visual><geometry><box size="0.022 0.015 0.017"/></geometry><origin rpy="0 0 0" xyz="0.011 0 0"/><material name="White"/></visual></link>
    
    <joint name="LeftLittleMPYaw" type="fixed">
        <origin rpy="1.57079632679 0 0.690626785" xyz="0.0427072303336 0.0352928446888 0.007747"/>
        <axis xyz="0 0 1"/>
        <parent link="LeftPalm"/>
        <child link="LeftMedialMetacarpal"/>
    </joint>
    <joint name="LeftLittleMPExtensor" type="fixed">
        <origin rpy="-0.690626785 0 1.57079632679" xyz="0 -0.010287 0.071327"/>
        <axis xyz="0 0 1"/>
        <parent link="LeftMedialMetacarpal"/>
        <child link="LeftLittleProximalPhalanx"/>
    </joint>
    <joint name="LeftLittlePIPExtensor" type="fixed">
        <origin rpy="0 0 -1.57079632679" xyz="0 -0.0381 -0.050169"/>
        <axis xyz="0 0 1"/>
        <parent link="LeftLittleProximalPhalanx"/>
        <child link="LeftLittleMedialPhalanx"/>
    </joint>
    <joint name="LeftLittleDIPExtensor" type="fixed">
        <origin rpy="0 0 0" xyz="0.02286 0 0"/>
        <axis xyz="0 0 1"/>
        <parent link="LeftLittleMedialPhalanx"/>
        <child link="LeftLittleDistalPhalanx"/>
    </joint>
    <link name="RightHipRotator">
        <inertial>
            <mass value="2.39"/>
            <origin rpy="0 0 0" xyz="0.001307857 0.021764163 0.038670367"/>
            <inertia ixx="0.0172609783333" ixy="0.0" ixz="0.0" iyy="0.0148661983333" iyz="0.0" izz="0.0112381783333"/>
        </inertial>
        
        
    <collision><geometry><sphere radius="0.12"/></geometry><origin xyz="0 0.01 -0.035"/></collision><visual><geometry><sphere radius="0.12"/></geometry><origin xyz="0 0.01 -0.035"/><material name="Gold"/></visual></link>
    
    <link name="RightHipAdductor">
        <inertial>
            <mass value="5.95"/>
            <origin rpy="0 0 0" xyz="0.024260044 0.019261751 -0.0018458616"/>
            <inertia ixx="0.0244713583333" ixy="0.0" ixz="0.0" iyy="0.0160104583333" iyz="0.0" izz="0.0254788916667"/>
        </inertial>
        
        
    </link>
    
    <link name="RightLeg">
        <inertial>
            <mass value="8.64"/>
            <origin rpy="0 0 0" xyz="0.25533364 -0.016460667 -0.035"/>
            <inertia ixx="0.07918056" ixy="0.0" ixz="0.0" iyy="0.2920464" iyz="0.0" izz="0.3124692"/>
        </inertial>
        
        
    <collision><geometry><box size="0.35 0.22 0.22"/></geometry><origin rpy="0 0 0" xyz="0.28 -0.03 -0.07"/></collision><collision><geometry><box size="0.194 0.22 0.1"/></geometry><origin rpy="0 0 0" xyz="0.008 -0.03 -0.13"/></collision><visual><geometry><box size="0.35 0.22 0.22"/></geometry><origin rpy="0 0 0" xyz="0.28 -0.03 -0.07"/><material name="White"/></visual><visual><geometry><box size="0.194 0.22 0.1"/></geometry><origin rpy="0 0 0" xyz="0.008 -0.03 -0.13"/></visual></link>
    
    <link name="RightShankStructure">
        <inertial>
            <mass value="8.002"/>
            <origin rpy="0 0 0" xyz="0.12342688 -0.0087741035 0.006614093"/>
            <inertia ixx="0.0504612788333" ixy="0.0" ixz="0.0" iyy="0.140171700833" iyz="0.0" izz="0.13887471"/>
        </inertial>
        
        
    <collision><geometry><box size="0.36 0.18 0.18"/></geometry><origin rpy="0 0 0" xyz="0.22 0.01 0.01"/></collision><visual><geometry><box size="0.36 0.18 0.18"/></geometry><origin rpy="0 0 0" xyz="0.22 0.01 0.01"/><material name="White"/></visual></link>
    
    <link name="RightAnkleYoke">
        <inertial>
            <mass value="0.395"/>
            <origin rpy="0 0 0" xyz="0.0057963439 0.0020433211 9.0424431e-05"/>
            <inertia ixx="0.000210699583333" ixy="0.0" ixz="0.0" iyy="5.64191666667e-05" iyz="0.0" izz="0.000225972916667"/>
        </inertial>
        
        
    </link>
    <link name="r_foot">
        <inertial>
            <mass value="1.888"/>
            <origin rpy="0 0.13 0" xyz="0.048263578 -3.1591183e-05 0.077849126"/>
            <inertia ixx="0.0167377493333" ixy="0.0" ixz="0.0" iyy="0.0152179093333" iyz="0.0" izz="0.00363565866667"/>
        </inertial>
        
        <collision>
            <origin rpy="0 0.13 0" xyz="0.048263578 -3.1591183e-05 0.077849126"/>
            <geometry>
                <box size="0.082 0.128 0.3"/>
            </geometry>
        <material name="White"/></collision>

    <collision>
      <origin rpy="0 0 0" xyz="0.075 0.0624435 -0.0775"/>
      <geometry>
        <sphere radius="0.0"/>
      </geometry>
    <material name="White"/></collision>
    
    <collision>
      <origin rpy="0 0 0" xyz="0.075 -0.0624435 -0.0775"/>
      <geometry>
        <sphere radius="0.0"/>
      </geometry>
    <material name="White"/></collision>
    
    <collision>
      <origin rpy="0 0 0" xyz="0.11 0.0624435 0.22"/>
      <geometry>
        <sphere radius="0.0"/>
      </geometry>
    <material name="White"/></collision>
    
    <collision>
      <origin rpy="0 0 0" xyz="0.11 -0.0624435 0.22"/>
      <geometry>
        <sphere radius="0.0"/>
      </geometry>
    <material name="White"/></collision>
    

    <visual><geometry><box size="0.082 0.128 0.3"/></geometry><origin rpy="0 0.13 0" xyz="0.048263578 -3.1591183e-05 0.077849126"/><material name="White"/></visual></link>
  <frame link="r_foot" name="r_foot_sole" rpy="0 -1.4408 0" xyz="0.0925 0 0.07125"/>
    
    
    <joint name="RightHipRotator" type="revolute">
        <origin rpy="0.0 0 -1.57079632679" xyz="0 -0.1016 -0.183"/>
        <axis xyz="0 0 1"/>
        <parent link="Pelvis"/>
        <child link="RightHipRotator"/>
        <limit effort="190" lower="-0.5235987753" upper="0.169296937347" velocity="5.89"/>
        <controller_gains Kd="500" Kp="15000"/>
        <dynamics damping="1.0" friction="0.0"/>
    </joint>
    
    <joint name="RightHipAdductor" type="revolute">
        <origin rpy="-1.57079632679 0 0" xyz="0 0 0"/>
        <axis xyz="0 0 1"/>
        <parent link="RightHipRotator"/>
        <child link="RightHipAdductor"/>
        <limit effort="350" lower="-0.5235987753" upper="0.26179938765" velocity="7"/>
        <controller_gains Kd="500" Kp="15000"/>
        <dynamics damping="1.0" friction="0.0"/>
    </joint>
    
    <joint name="RightHipExtensor" type="revolute">
        <origin rpy="-1.57079632679 0 1.57079632679" xyz="0 0.061 0"/>
        <axis xyz="0 0 1"/>
        <parent link="RightHipAdductor"/>
        <child link="RightLeg"/>
        <limit effort="350" lower="-2.35619448885" upper="1.71042266598" velocity="6.11"/>
        <controller_gains Kd="500" Kp="15000"/>
        <dynamics damping="1.0" friction="0.0"/>
    </joint>
    
    <joint name="RightKneeExtensor" type="revolute">
        <origin rpy="3.14159265359 0 0" xyz="0.431 0 -0.0374"/>
        <axis xyz="0 0 1"/>
        <parent link="RightLeg"/>
        <child link="RightShankStructure"/>
        <limit effort="350" lower="-1.90240888359" upper="0.218166156375" velocity="6.11"/>
        <controller_gains Kd="500" Kp="15000"/>
        <dynamics damping="1.0" friction="0.0"/>
    </joint>
    
    <joint name="RightAnkleExtensor" type="revolute">
        <origin rpy="3.14159265359 0 0" xyz="0.406 0 0"/>
        <axis xyz="0 0 1"/>
        <parent link="RightShankStructure"/>
        <child link="RightAnkleYoke"/>
        <limit effort="205" lower="-0.8726646255" upper="0.8726646255" velocity="11"/>
        <controller_gains Kd="400" Kp="15000"/>
        <dynamics damping="1.0" friction="0.0"/>
    </joint>
    
    <joint name="RightAnkle" type="revolute">
        <origin rpy="1.57079632679 0 -0.13" xyz="0.0127 0 0"/>
        <axis xyz="0 0 1"/>
        <parent link="RightAnkleYoke"/>
        <child link="r_foot"/>
        <limit effort="205" lower="-0.3490658502" upper="0.3490658502" velocity="11"/>
        <controller_gains Kd="400" Kp="15000"/>
        <dynamics damping="0.3"/>
    </joint>
    
    
    
    
    
    
    
    
    
    
    
    
    
    <link name="RightLegHokuyo_Frame">
        <!-- Virtual Link -->
        <inertial>
            <mass value="0.1"/>
            <origin rpy="0 0 0" xyz="0 0 0"/>
            <inertia ixx="8.33333333333e-05" ixy="0.0" ixz="0.0" iyy="8.33333333333e-05" iyz="0.0" izz="0.000125"/>
        </inertial>
    </link>
    
    <joint name="RightLegHokuyo_Offset" type="fixed">
        <origin rpy="1.57079632679 0 -0.38394" xyz="0.350849 -0.098349 -0.036021"/>
        <axis xyz="0 0 1"/>
        <parent link="RightLeg"/>
        <child link="RightLegHokuyo_Frame"/>
    </joint>
    <link name="RightLegCamBoard_Frame">
        <!-- Virtual Link -->
        <inertial>
            <mass value="0.1"/>
            <origin rpy="0 0 0" xyz="0 0 0"/>
            <inertia ixx="8.33333333333e-05" ixy="0.0" ixz="0.0" iyy="8.33333333333e-05" iyz="0.0" izz="0.000125"/>
        </inertial>
    </link>
    
    <joint name="RightLegCamBoard_Offset" type="fixed">
        <origin rpy="-1.57079632679 0 1.3" xyz="0.344887 0.069118 -0.0085"/>
        <axis xyz="0 0 1"/>
        <parent link="RightShankStructure"/>
        <child link="RightLegCamBoard_Frame"/>
    </joint>
    <link name="RightLegCamBoardIR_Frame">
        <!-- Virtual Link -->
        <inertial>
            <mass value="0.1"/>
            <origin rpy="0 0 0" xyz="0 0 0"/>
            <inertia ixx="8.33333333333e-05" ixy="0.0" ixz="0.0" iyy="8.33333333333e-05" iyz="0.0" izz="0.000125"/>
        </inertial>
    </link>
    <joint name="RightLegCamBoardIR_Offset" type="fixed">
        <origin rpy="-1.4279169 0.057186 -1.603747" xyz="-0.05180 -0.0013 0.030237"/>
        <axis xyz="0 0 1"/>
        <parent link="RightLegCamBoard_Frame"/>
        <child link="RightLegCamBoardIR_Frame"/>
    </joint>
    <link name="RightCOP_Frame">
        <!-- Virtual Link -->
        <inertial>
            <mass value="0.1"/>
            <origin rpy="0 0 0" xyz="0 0 0"/>
            <inertia ixx="8.33333333333e-05" ixy="0.0" ixz="0.0" iyy="8.33333333333e-05" iyz="0.0" izz="0.000125"/>
        </inertial>
    </link>
    <joint name="RightCOP_Offset" type="fixed">
        <origin rpy="0.0 -1.57079632679 0" xyz="0.0845 0 0"/>
        <axis xyz="0 0 1"/>
        <parent link="r_foot"/>
        <child link="RightCOP_Frame"/>
    </joint>
    <link name="RightLeg6Axis_Frame">
        <!-- Virtual Link -->
        <inertial>
            <mass value="0.1"/>
            <origin rpy="0 0 0" xyz="0 0 0"/>
            <inertia ixx="8.33333333333e-05" ixy="0.0" ixz="0.0" iyy="8.33333333333e-05" iyz="0.0" izz="0.000125"/>
        </inertial>
    </link>
    <joint name="RightLeg6Axis_Offset" type="fixed">
        <origin rpy="0 0  0" xyz="0.058547 0 0.0215"/>
        <axis xyz="0 0 1"/>
        <parent link="r_foot"/>
        <child link="RightLeg6Axis_Frame"/>
    </joint>
    <link name="RightLegHermes_Frame">
        <!-- Virtual Link -->
        <inertial>
            <mass value="0.1"/>
            <origin rpy="0 0 0" xyz="0 0 0"/>
            <inertia ixx="8.33333333333e-05" ixy="0.0" ixz="0.0" iyy="8.33333333333e-05" iyz="0.0" izz="0.000125"/>
        </inertial>
    </link>
    <joint name="RightLegHermes_Offset" type="fixed">
        <origin rpy="0.0 -1.57079632679 0" xyz="0.0845 0 0"/>
        <axis xyz="0 0 1"/>
        <parent link="r_foot"/>
        <child link="RightLegHermes_Frame"/>
    </joint>
    <link name="RightMPU6000_Frame">
        <!-- Virtual Link -->
        <inertial>
            <mass value="0.1"/>
            <origin rpy="0 0 0" xyz="0 0 0"/>
            <inertia ixx="8.33333333333e-05" ixy="0.0" ixz="0.0" iyy="8.33333333333e-05" iyz="0.0" izz="0.000125"/>
        </inertial>
    </link>
    <joint name="RightMPU6000_Offset" type="fixed">
        <origin rpy="0 1.44079632679 3.14159265358" xyz="0.0471 0.00722 0.0843"/>
        <axis xyz="0 0 1"/>
        <parent link="r_foot"/>
        <child link="RightMPU6000_Frame"/>
    </joint>
    
    
    <link name="LeftHipRotator">
        <inertial>
            <mass value="2.39"/>
            <origin rpy="0 0 0" xyz="0.001307857 0.021764163 -0.038670367"/>
            <inertia ixx="0.0172609783333" ixy="0.0" ixz="0.0" iyy="0.0148661983333" iyz="0.0" izz="0.0112381783333"/>
        </inertial>
        
        
    <collision><geometry><sphere radius="0.12"/></geometry><origin xyz="0 0.01 0.035"/></collision><visual><geometry><sphere radius="0.12"/></geometry><origin xyz="0 0.01 0.035"/><material name="Gold"/></visual></link>
    
    <link name="LeftHipAdductor">
        <inertial>
            <mass value="5.95"/>
            <origin rpy="0 0 0" xyz="0.024260044 0.019261751 -0.0018458616"/>
            <inertia ixx="0.0244713583333" ixy="0.0" ixz="0.0" iyy="0.0160104583333" iyz="0.0" izz="0.0254788916667"/>
        </inertial>
        
        
    </link>
    
    <link name="LeftLeg">
        <inertial>
            <mass value="8.64"/>
            <origin rpy="0 0 0" xyz="0.25533364 -0.016460667 0.035"/>
            <inertia ixx="0.07918056" ixy="0.0" ixz="0.0" iyy="0.2920464" iyz="0.0" izz="0.3124692"/>
        </inertial>
        
        
    <collision><geometry><box size="0.35 0.22 0.22"/></geometry><origin rpy="0 0 0" xyz="0.28 -0.03 0.07"/></collision><collision><geometry><box size="0.194 0.22 0.1"/></geometry><origin rpy="0 0 0" xyz="0.008 -0.03 0.13"/></collision><visual><geometry><box size="0.35 0.22 0.22"/></geometry><origin rpy="0 0 0" xyz="0.28 -0.03 0.07"/><material name="White"/></visual><visual><geometry><box size="0.194 0.22 0.1"/></geometry><origin rpy="0 0 0" xyz="0.008 -0.03 0.13"/></visual></link>
    
    <link name="LeftShankStructure">
        <inertial>
            <mass value="8.002"/>
            <origin rpy="0 0 0" xyz="0.12342688 -0.0087741035 -0.006614093"/>
            <inertia ixx="0.0504612788333" ixy="0.0" ixz="0.0" iyy="0.140171700833" iyz="0.0" izz="0.13887471"/>
        </inertial>
        
        
    <collision><geometry><box size="0.36 0.18 0.18"/></geometry><origin rpy="0 0 0" xyz="0.22 0.01 -0.01"/></collision><visual><geometry><box size="0.36 0.18 0.18"/></geometry><origin rpy="0 0 0" xyz="0.22 0.01 -0.01"/><material name="White"/></visual></link>
    
    <link name="LeftAnkleYoke">
        <inertial>
            <mass value="0.395"/>
            <origin rpy="0 0 0" xyz="0.0057963439 0.0020433211 9.0424431e-05"/>
            <inertia ixx="0.000210699583333" ixy="0.0" ixz="0.0" iyy="5.64191666667e-05" iyz="0.0" izz="0.000225972916667"/>
        </inertial>
        
        
    </link>
    <link name="l_foot">
        <inertial>
            <mass value="1.888"/>
            <origin rpy="0 -0.13 0" xyz="0.048263578 -3.1591183e-05 -0.077849126"/>
            <inertia ixx="0.0167377493333" ixy="0.0" ixz="0.0" iyy="0.0152179093333" iyz="0.0" izz="0.00363565866667"/>
        </inertial>
        
        <collision>
            <origin rpy="0 -0.13 0" xyz="0.048263578 -3.1591183e-05 -0.077849126"/>
            <geometry>
                <box size="0.082 0.128 0.3"/>
            </geometry>
        <material name="White"/></collision>

    <collision>
      <origin rpy="0 0 0" xyz="0.075 0.0624435 0.0775"/>
      <geometry>
        <sphere radius="0.0"/>
      </geometry>
    <material name="White"/></collision>
    
    <collision>
      <origin rpy="0 0 0" xyz="0.075 -0.0624435 0.0775"/>
      <geometry>
        <sphere radius="0.0"/>
      </geometry>
    <material name="White"/></collision>
    
    <collision>
      <origin rpy="0 0 0" xyz="0.11 0.0624435 -0.22"/>
      <geometry>
        <sphere radius="0.0"/>
      </geometry>
    <material name="White"/></collision>
    
    <collision>
      <origin rpy="0 0 0" xyz="0.11 -0.0624435 -0.22"/>
      <geometry>
        <sphere radius="0.0"/>
      </geometry>
    <material name="White"/></collision>
    

    <visual><geometry><box size="0.082 0.128 0.3"/></geometry><origin rpy="0 -0.13 0" xyz="0.048263578 -3.1591183e-05 -0.077849126"/><material name="White"/></visual></link>
  <frame link="l_foot" name="l_foot_sole" rpy="3.1416 1.4408 0" xyz="0.0925 0 -0.07125"/>
<!--  <frame name="l_foot_sole" xyz="0.082 0 -0.14" rpy="3.1416 1.5708 0" link="l_foot"/> -->
    
    
    <joint name="LeftHipRotator" type="revolute">
        <origin rpy="3.14159265359 0 1.57079632679" xyz="0 0.1016 -0.183"/>
        <axis xyz="0 0 1"/>
        <parent link="Pelvis"/>
        <child link="LeftHipRotator"/>
        <limit effort="190" lower="-0.5235987753" upper="0.169296937347" velocity="5.89"/>
        <controller_gains Kd="500" Kp="15000"/>
        <dynamics damping="1.0" friction="0.0"/>
    </joint>
    
    <joint name="LeftHipAdductor" type="revolute">
        <origin rpy="1.57079632679 0 0" xyz="0 0 0"/>
        <axis xyz="0 0 1"/>
        <parent link="LeftHipRotator"/>
        <child link="LeftHipAdductor"/>
        <limit effort="350" lower="-0.5235987753" upper="0.26179938765" velocity="7"/>
        <controller_gains Kd="500" Kp="15000"/>
        <dynamics damping="1.0" friction="0.0"/>
    </joint>
    
    <joint name="LeftHipExtensor" type="revolute">
        <origin rpy="1.57079632679 0 1.57079632679" xyz="0 0.061 0"/>
        <axis xyz="0 0 1"/>
        <parent link="LeftHipAdductor"/>
        <child link="LeftLeg"/>
        <limit effort="350" lower="-2.35619448885" upper="1.71042266598" velocity="6.11"/>
        <controller_gains Kd="500" Kp="15000"/>
        <dynamics damping="1.0" friction="0.0"/>
    </joint>
    
    <joint name="LeftKneeExtensor" type="revolute">
        <origin rpy="3.14159265359 0 0" xyz="0.431 0 0.0374"/>
        <axis xyz="0 0 1"/>
        <parent link="LeftLeg"/>
        <child link="LeftShankStructure"/>
        <limit effort="350" lower="-1.90240888359" upper="0.218166156375" velocity="6.11"/>
        <controller_gains Kd="500" Kp="15000"/>
        <dynamics damping="1.0" friction="0.0"/>
    </joint>
    
    <joint name="LeftAnkleExtensor" type="revolute">
        <origin rpy="3.14159265359 0 0" xyz="0.406 0 0"/>
        <axis xyz="0 0 1"/>
        <parent link="LeftShankStructure"/>
        <child link="LeftAnkleYoke"/>
        <limit effort="205" lower="-0.8726646255" upper="0.8726646255" velocity="11"/>
        <controller_gains Kd="400" Kp="15000"/>
        <dynamics damping="1.0" friction="0.0"/>
    </joint>
    
    <joint name="LeftAnkle" type="revolute">
        <origin rpy="-1.57079632679 0 -0.13" xyz="0.0127 0 0"/>
        <axis xyz="0 0 1"/>
        <parent link="LeftAnkleYoke"/>
        <child link="l_foot"/>
        <limit effort="205" lower="-0.3490658502" upper="0.3490658502" velocity="11"/>
        <controller_gains Kd="400" Kp="15000"/>
        <dynamics damping="0.3"/>
    </joint>
    
    
    
    
    
    
    
    
    
    
    
    
    
    <link name="LeftLegHokuyo_Frame">
        <!-- Virtual Link -->
        <inertial>
            <mass value="0.1"/>
            <origin rpy="0 0 0" xyz="0 0 0"/>
            <inertia ixx="8.33333333333e-05" ixy="0.0" ixz="0.0" iyy="8.33333333333e-05" iyz="0.0" izz="0.000125"/>
        </inertial>
    </link>
    
    <joint name="LeftLegHokuyo_Offset" type="fixed">
        <origin rpy="1.57079632679 0 -0.38394" xyz="0.350849 -0.098349 0.036021"/>
        <axis xyz="0 0 1"/>
        <parent link="LeftLeg"/>
        <child link="LeftLegHokuyo_Frame"/>
    </joint>
    <link name="LeftLegCamBoard_Frame">
        <!-- Virtual Link -->
        <inertial>
            <mass value="0.1"/>
            <origin rpy="0 0 0" xyz="0 0 0"/>
            <inertia ixx="8.33333333333e-05" ixy="0.0" ixz="0.0" iyy="8.33333333333e-05" iyz="0.0" izz="0.000125"/>
        </inertial>
    </link>
    
    <joint name="LeftLegCamBoard_Offset" type="fixed">
        <origin rpy="-1.57079632679 0 1.3" xyz="0.344887 0.069118 0.0085"/>
        <axis xyz="0 0 1"/>
        <parent link="LeftShankStructure"/>
        <child link="LeftLegCamBoard_Frame"/>
    </joint>
    <link name="LeftLegCamBoardIR_Frame">
        <!-- Virtual Link -->
        <inertial>
            <mass value="0.1"/>
            <origin rpy="0 0 0" xyz="0 0 0"/>
            <inertia ixx="8.33333333333e-05" ixy="0.0" ixz="0.0" iyy="8.33333333333e-05" iyz="0.0" izz="0.000125"/>
        </inertial>
    </link>
    <joint name="LeftLegCamBoardIR_Offset" type="fixed">
        <origin rpy="-1.4279169 0.057186 -1.603747" xyz="-0.05180 -0.0013 0.030237"/>
        <axis xyz="0 0 1"/>
        <parent link="LeftLegCamBoard_Frame"/>
        <child link="LeftLegCamBoardIR_Frame"/>
    </joint>
    <link name="LeftCOP_Frame">
        <!-- Virtual Link -->
        <inertial>
            <mass value="0.1"/>
            <origin rpy="0 0 0" xyz="0 0 0"/>
            <inertia ixx="8.33333333333e-05" ixy="0.0" ixz="0.0" iyy="8.33333333333e-05" iyz="0.0" izz="0.000125"/>
        </inertial>
    </link>
    <joint name="LeftCOP_Offset" type="fixed">
        <origin rpy="3.14159265358 1.57079632679 0" xyz="0.0845 0 0"/>
        <axis xyz="0 0 1"/>
        <parent link="l_foot"/>
        <child link="LeftCOP_Frame"/>
    </joint>
    <link name="LeftLeg6Axis_Frame">
        <!-- Virtual Link -->
        <inertial>
            <mass value="0.1"/>
            <origin rpy="0 0 0" xyz="0 0 0"/>
            <inertia ixx="8.33333333333e-05" ixy="0.0" ixz="0.0" iyy="8.33333333333e-05" iyz="0.0" izz="0.000125"/>
        </inertial>
    </link>
    <joint name="LeftLeg6Axis_Offset" type="fixed">
        <origin rpy="0 0 0" xyz="0.058547 0 -0.0215"/>
        <axis xyz="0 0 1"/>
        <parent link="l_foot"/>
        <child link="LeftLeg6Axis_Frame"/>
    </joint>
    <link name="LeftLegHermes_Frame">
        <!-- Virtual Link -->
        <inertial>
            <mass value="0.1"/>
            <origin rpy="0 0 0" xyz="0 0 0"/>
            <inertia ixx="8.33333333333e-05" ixy="0.0" ixz="0.0" iyy="8.33333333333e-05" iyz="0.0" izz="0.000125"/>
        </inertial>
    </link>
    <joint name="LeftLegHermes_Offset" type="fixed">
        <origin rpy="3.14159265358 1.57079632679 0" xyz="0.0845 0 0"/>
        <axis xyz="0 0 1"/>
        <parent link="l_foot"/>
        <child link="LeftLegHermes_Frame"/>
    </joint>
    <link name="LeftMPU6000_Frame">
        <!-- Virtual Link -->
        <inertial>
            <mass value="0.1"/>
            <origin rpy="0 0 0" xyz="0 0 0"/>
            <inertia ixx="8.33333333333e-05" ixy="0.0" ixz="0.0" iyy="8.33333333333e-05" iyz="0.0" izz="0.000125"/>
        </inertial>
    </link>
    <joint name="LeftMPU6000_Offset" type="fixed">
        <origin rpy="0 -1.70079632679 0.0" xyz="0.0471 -0.00722 -0.0843"/>
        <axis xyz="0 0 1"/>
        <parent link="l_foot"/>
        <child link="LeftMPU6000_Frame"/>
    </joint>
    
    
  
  
  
  
  
  
  
  
  
  
  
  
  
  
  
  
  
  
  
  
  
  
  
  
  
  
  
  
  
  
</robot>