<?xml version="1.0"?>
<robot name="pendulum">
    <!-- materials -->
    <material name="blue">
        <color rgba="0.2 0.4 0.6 1"/>
    </material>

    <material name="red">
        <color rgba="0.9 0.7 0.2 1"/>
    </material>

    <!-- links -->
    <link name="base_link">
        <visual>
            <geometry>
                <cylinder length="0.3" radius="0.04"/>
            </geometry>
            <origin rpy="0 1.57075 0" xyz="0 0 0"/>
            <material name="blue"/>
        </visual>
    </link>

    <link name="arm">
        <visual>
            <geometry>
                <cylinder length="1" radius="0.015"/>
            </geometry>
            <origin rpy="0 0 0" xyz="0 0 -0.5"/>
            <material name="blue"/>
        </visual>
    </link>

    <link name="mass">
        <visual>
            <geometry>
                <!-- <sphere radius="0.1"/> -->
                <box size="0.1 0.1 0.1"/>
            </geometry>
            <origin rpy="0 0 0" xyz="0 0 -1"/>
            <material name="red"/>
        </visual>

        <!-- the pendulum rotates around the y plane -->
        <inertia>
            <mass value="1"/>
            <!-- m * r ^ 2, where m = 1, r = 1 -->
            <inertia ixx="0" ixy="0" ixz="0" iyy="1" iyz="0" izz="0"/>
        </inertia>
    </link>

    <!-- joints -->
    <!-- the pole and base are massless -->
    <joint name="base_to_arm" type="continuous">
        <parent link="base_link"/>
        <child link="arm"/>
        <origin xyz="0 0 0"/>
        <axis xyz="0 1 0"/>
    </joint>

    <!-- the mass stays fixed to the pole -->
    <joint name="arm_to_mass" type="fixed">
        <parent link="arm"/>
        <child link="mass"/>
        <origin xyz="0 0 0"/>
    </joint>
</robot>