<?xml version="1.0" ?>
<robot name="rr_bot">
    <link name="base_link" />
    <link name="link1">
        <visual>
            <origin rpy="0 1.57079 0" xyz="0.07 0 0"/>
            <geometry>
                <cylinder length="0.14" radius=".005"/>
            </geometry>
            <material name="Cyan">
                <color rgba="0 1.0 1.0 1.0"/>
            </material>
        </visual>
    </link>
    <link name="link2">
        <visual>
            <origin rpy="0 1.57079 0" xyz="0.07 0 0"/>
            <geometry>
                <cylinder length="0.14" radius="0.005"/>
            </geometry>
            <material name="Cyan">
                <color rgba="0 1.0 1.0 1.0"/>
            </material>
        </visual>
    </link>
    <link name="link3" />
    <joint name="joint1" type="revolute">
        <parent link="base_link"/>
        <child link="link1"/>
        <origin rpy="0 0 0" xyz="0 0 0"/>
        <axis xyz="0 0 1"/>
        <limit effort="1" lower="-2.9" upper="2.9" velocity="2" />
    </joint>
    <joint name="joint2" type="revolute">
        <parent link="link1"/>
        <child link="link2"/>
        <origin rpy="0 0 0" xyz="0.14 0 0"/>
        <axis xyz="0 0 1"/>
        <limit effort="1" lower="-2.9" upper="2.9" velocity="2" />
    </joint>
    <joint name="end_effector" type="fixed">
        <parent link="link2"/>
        <child link="link3"/>
        <origin rpy="0 0 0" xyz="0.14 0 0"/>
    </joint>
</robot>